Workbook
Name FCI: [1]DCFROR!#REF!
Name KeyList: Data!A2:A9
Name S: 'PV Sizing'!$D$27
Name S: 'Sizing code'!$D$27

Sheet Flowsheet

Sheet MOC
A1: Equipment description and materials from the Humbird 2011 Report
A3: Area 100 | F3: Area 500
A4: EQPT NO | B4: EQUIPMENT TITLE | C4: DESCRIPTION | D4: MATERIAL | F4: EQPT NO | G4: EQUIPMENT TITLE | H4: DESCRIPTION | I4: MATERIAL
A5: C-101 | B5: Transfer Conveyor | C5: 160 MTPH ea., enclosed, 60 in. x 65 ft. long | D5: CS | F5: A-530 | G5: Filtrate Tank Agitator | I5: SS
A6: C-102 | B6: High Angle Transfer Conveyor | C6: 160 MTPH ea., enclosed, 72 in. wide | D6: CS | F6: C-501 | G6: Lignin Wet Cake Conveyor | H6: Belt 100 ft. long x 24" wide, enclosed | I6: SS304
A7: C-103 | B7: Reversing Load-in Conveyor | C7: 320 MT/hr, enclosed, 84 in. wide | D7: CS | F7: C-502 | G7: Lignin Wet Cake Screw | H7: Screw conveyor - 25 ft lg x 14" dia | I7: SS304
A8: C-104 | B8: Dome Reclaim System | C8: 100 MTPH ea. | D8: CS | F8: D-501 | G8: Beer Column | H8: 14' dia. x 76' tall, 32 trays, 24" spacing | I8: 316SS
A9: C-105 | B9: Reclaim Conveyor | C9: 100 MTPH ea., enclosed, 48 in. x 125 ft. long | D9: CS | F9: D-502 | G9: Rectification Column | H9: Top 13' dia. x 68' h, Bottom 4'6" x 31' h | I9: 316SS
A10: C-106 | B10: High Angle Transfer Conveyor | C10: 100 MTPH, enclosed, 72 in. wide | D10: CS | F10: H-501 | G10: Beer Column Reboiler | H10: S & T | I10: 316SS;CS
A11: C-107 | B11: Elevated Transfer Conveyor | C11: 100 MTPH, enclosed, 48 in. x 200 ft. long | D11: CS | F11: H-502 | G11: Rectification Column Reboiler | H11: S & T | I11: 316SS;CS
A12: C-108 | B12: Process Feed Conveyor | C12: 70 MTPH ea., enclosed, 42 in. x 25 ft. long | D12: CS | F12: H-504 | G12: Beer Column Condenser | H12: S & T | I12: 316SS;CS
A13: M-101 | B13: Truck Scale | C13: 10' x 70', 200,000 lb | D13: CONCRETE | F13: H-505 | G13: Rectification Column Condenser | H13: 92.2 MM Btu/hr 3 cells | I13: CS
A14: M-102 | B14: Truck Dumper | C14: 70' x 55 ton x 63 degree | D14: CS | F14: H-512 | G14: Beer Column Feed Interchanger | H14: Plate & Frame | I14: 316SS
A15: M-103 | B15: Truck Dumper Hopper | C15: 3500 cu.ft. hopper w/ drag chain conveyor | D15: CS | F15: M-503 | G15: Molecular Sieve Package (9 pieces) | I15: SS
A16: M-104 | B16: Concrete Feedstock Storage Dome | C16: 98 ft. dia., 160 ft. high., 4000 MT | D16: CONCRETE | F16: M-505 | G16: Pressure Filter Pressing Compr | H16: 460 SCFM, 300 psig | I16: SS
A17: M-105 | B17: Belt Scale | C17: Scale plus processor | D17: CS | F17: M-507 | G17: Pressure Filter Drying Compr | H17: 4000 SCFM, 130 psig (ea) | I17: SS
A18: M-106 | B18: Dust Collection System | C18: 8500 ACFM | D18: CS | F18: P-501 | G18: Beer Column Bottoms Recirc Pump | H18: 10,000 gpm | I18: 316SS
F19: P-502 | G19: Beer Column Reflux Pump | H19: 15 gpm | I19: 316SS
A20: Area 200 | F20: P-504 | G20: Rectification Column Bottoms Pump | H20: 500 gpm | I20: 316SS
A21: EQPT NO | B21: EQUIPMENT TITLE | C21: DESCRIPTION | D21: MATERIAL | F21: P-505 | G21: Rectification Column Reflux Pump | H21: 500 gpm | I21: 316SS
A22: A-201 | B22: In-line Sulfuric Acid Mixer | C22: Kynar Lined - 600 gpm H2O - 5 gpm acid | D22: SS304 | F22: P-506 | G22: Beer Column Stillage Pump | H22: 2000 gpm | I22: 316SS
A23: A-203 | B23: Blowdown Tank Agitator | C23: Side-mounted, 3 x 75 hp. (170 kW) | D23: 316LSS | F23: P-515 | G23: Scrubber Bottoms Pump | H23: 108 GPM, 104 FT TDH | I23: 316SS
A24: A-204 | B24: Flash Tank Agitator | C24: Side-mounted, 3 x 75 hp. (170 kW) | D24: 316LSS | F24: P-530 | G24: Filtrate Tank Discharge Pump | H24: 590 GPM, 100 FT TDH SIZE 4X3-13 | I24: SS
A25: A-208 | B25: Oligomer Hold Tank Agitator | C25: Side-mounted, 3 x 75 hp. (170 kW) | D25: 316LSS | F25: P-531 | G25: Feed Pump | H25: 1014 GPM 230 FT TDH SIZE 8X6-15 | I25: SS
A26: A-210 | B26: Ammonia Addition Tank Agitator | D26: SS | F26: P-532 | G26: Manifold Flush Pump | I26: SS
A27: A-214 | B27: Ammonia Static Mixer | D27: SS | F27: P-533 | G27: Cloth Wash Pump | I27: SS
A28: A-224 | B28: Reacidification Tank Agitator | D28: SS | F28: P-581 | G28: Filtrate Discharge Pump | H28: 590 GPM, 100 FT TDH SIZE 4X3-13 | I28: SS
A29: C-201 | B29: Transfer Conveyor | C29: 800 mm x 7600 mm (2'-8" x 25') | D29: AL-6XN | F29: S-505 | G29: Pressure Filter | H29: 384 sq. m filtration area ea incl packing | I29: SS316
A30: C-202 | B30: Distribution Conveyor | C30: 800 mm x 7600 mm (2'-8" x 25') | D30: AL-6XN | F30: T-503 | G30: Beer Column Reflux Drum | H30: 4' dia, 6' high, 50 psig design | I30: 316SS
A31: C-203 | B31: Overfeed Conveyor | C31: 800 mm x 7600 mm (2'-8" x 25') | D31: AL-6XN | F31: T-505 | G31: Rectification Column Reflux Drum | H31: 4' dia, 6' high, 50 psig design | I31: 316SS
A32: C-204 | B32: Pressurized Heating Screw | C32: 2500 mm x 9500 mm (8' x 31') | D32: Dup. 2205 | F32: T-512 | G32: Vent Scrubber | H32: Inlet Gas: 9681 acfm, 91F, 1.97 mass% Ethanol | I32: SS304;PP
A33: C-205 | B33: Pressurized Pre-heater Discharge | C33: 850 mm x 3500 mm (2'-10" x 12') | D33: Dup. 2205 | F33: T-530 | G33: Filtrate Tank | H33: 13,750 gal 14' dia x 12' H | I33: SS
A34: C-206 | B34: Pressurized Transport - No. 1 | C34: 900 mm x 3500 mm (3' x 12') | D34: CLAD; CS | F34: T-531 | G34: Feed Tank | H34: 20,300 gal 14' dia x 18' H | I34: SS
A35: C-207 | B35: Pressurized Transport - No. 2 | C35: 1200 mm x 3500 mm (4' x 12') | D35: Incoloy 825; CLAD; CS | F35: T-532 | G35: Recycled Water Tank | H35: 4000 gal | I35: HDPE
A36: H-201 | B36: Pretreatment Water Heater | C36: 29.9 MMBtu | D36: 304SS | F36: T-533 | G36: Pressing Air Compressor Receiver | H36: 1350 gal., 300 psig design | I36: CS
A37: H-244 | B37: Waste Vapor Condenser | C37: Copied H-201 | D37: 304SS | F37: T-534 | G37: Drying Air Compressor Receiver | H37: 9,000 gal., 150 psig design | I37: CS
A38: M-201 | B38: Doffing Roll Storage Bins | C38: 60 cu. m. (2100 cu.ft.) with conveyors/scrapers | D38: 304LSS
A39: M-202 | B39: Pin Drum Feeder | D39: 316LSS | F39: Area 600 & 700
A40: M-203 | B40: Plug Screw Feeder | D40: 316LSS | F40: EQPT NO | G40: EQUIPMENT TITLE | H40: DESCRIPTION | I40: MATERIAL
A41: M-204 | B41: Prehydrolysis / Vertical Preheater | C41: 16' x 62' - 10 min. residence time | D41: Dup. 2205 | F41: B-606 | G41: Biogas Blower | H41: 3000 ACFM, 10 PSI | I41: CS
...

Sheet Stream table
B2: CIP | C2: CSL | D2: CSL1 | E2: CSL2 | F2: DAP | G2: DAP1 | H2: DAP2 | I2: FGD_lime | J2: RO_treated_water | K2: Stover | L2: air | M2: air_lagoon | N2: ammonia | O2: ammonia_process_water | P2: ash | Q2: beer | R2: biogas | S2: blowdown | T2: boiler_chemicals | U2: brine | V2: caustic | W2: cellulase | X2: denaturant | Y2: emissions | Z2: ethanol | AA2: evaporated_water | AB2: fire_water | AC2: gas_to_boiler | AD2: makeup_RO_water | AE2: makeup_process_water | AF2: makeup_water | AG2: natural_gas | AH2: plant_air | AI2: pretreated_biomass | AJ2: pretreatment_steam | AK2: pretreatment_wastewater | AL2: recycle_process_water | AM2: saccharification_water | AN2: sludge | AO2: slurry | AP2: stillage | AQ2: stripping_water | AR2: sulfuric_acid | AS2: to_boiler | AT2: vent | AU2: warm_process_water_1 | AV2: warm_process_water_2 | AW2: s1 | AX2: s2 | AY2: s3 | AZ2: s4 | BA2: s5 | BB2: s6 | BC2: s7 | BD2: s8 | BE2: s9 | BF2: s10 | BG2: s11 | BH2: s12 | BI2: s13 | BJ2: s14 | BK2: s15 | BL2: s16 | BM2: s17 | BN2: s18 | BO2: s19 | BP2: s20 | BQ2: s21 | BR2: s22 | BS2: s23 | BT2: s24 | BU2: s25 | BV2: s26 | BW2: s27 | BX2: s28 | BY2: s29 | BZ2: s30 | CA2: s31 | CB2: s32 | CC2: s33 | CD2: s34 | CE2: s35 | CF2: s36 | CG2: s37 | CH2: s38 | CI2: s39 | CJ2: s40 | CK2: s41 | CL2: s42 | CM2: s43 | CN2: s44 | CO2: s45 | CP2: s46 | CQ2: s47 | CR2: s48 | CS2: s49 | CT2: s50 | CU2: s51 | CV2: s52 | CW2: s54 | CX2: s55 | CY2: s56 | CZ2: s57 | DA2: s58 | DB2: s59 | DC2: s60 | DD2: s61 | DE2: s62 | DF2: s63 | DG2: s64 | DH2: s65 | DI2: s66 | DJ2: s67 | DK2: s68 | DL2: s69 | DM2: s70
A3: Source | B3: - | C3: - | D3: S302 | E3: S302 | F3: - | G3: S301 | H3: S301 | I3: - | J3: S604 | K3: - | L3: - | M3: - | N3: - | O3: - | P3: BT | Q3: T302 | R3: R601 | S3: BT | T3: - | U3: S604 | V3: - | W3: - | X3: - | Y3: BT | Z3: T703 | AA3: R602 | AB3: - | AC3: M2 | AD3: - | AE3: - | AF3: - | AG3: - | AH3: - | AI3: P202 | AJ3: - | AK3: H201 | AL3: P403 | AM3: - | AN3: S603 | AO3: R301 | AP3: H401 | AQ3: - | AR3: - | AS3: M1 | AT3: D401 | AU3: - | AV3: - | AW3: U101 | AX3: H2SO4_storage | AY3: T201 | AZ3: M201 | BA3: M203 | BB3: R201 | BC3: R201 | BD3: P201 | BE3: T202 | BF3: F201 | BG3: F201 | BH3: M204 | BI3: Ammonia_storage | BJ3: M205 | BK3: T203 | BL3: M301 | BM3: H301 | BN3: DAP_storage | BO3: CSL_storage | BP3: R303 | BQ3: R302 | BR3: R302 | BS3: T301 | BT3: R303 | BU3: R303 | BV3: M401 | BW3: M304 | BX3: D401 | BY3: D402 | BZ3: P401 | CA3: D402 | CB3: P402 | CC3: H401 | CD3: M402 | CE3: D403 | CF3: D403 | CG3: H402 | CH3: U401 | CI3: U401 | CJ3: H403 | CK3: T701 | CL3: P701 | CM3: T702 | CN3: P702 | CO3: M701 | CP3: - | CQ3: S401 | CR3: S401 | CS3: M601 | CT3: WWTC | CU3: R601 | CV3: R601 | CW3: M604 | CX3: M602 | CY3: R602 | CZ3: S601 | DA3: S601 | DB3: S602 | DC3: S602 | DD3: M603 | DE3: S603 | DF3: CIP | DG3: ADP | DH3: FWT | DI3: M3 | DJ3: M4 | DK3: PWC | DL3: PWC | DM3: PWC
A4: Sink | B4: CIP | C4: CSL_storage | D4: R302 | E4: R303 | F4: DAP_storage | G4: R302 | H4: R303 | I4: BT | J4: M4 | K4: U101 | L4: BT | M4: R602 | N4: Ammonia_storage | O4: M205 | P4: - | Q4: P401 | R4: M2 | S4: - | T4: BT | U4: - | V4: R602 | W4: M301 | X4: T702 | Y4: - | Z4: - | AA4: - | AB4: FWT | AC4: BT | AD4: PWC | AE4: PWC | AF4: BT | AG4: BT | AH4: ADP | AI4: M301 | AJ4: M203 | AK4: M601 | AL4: M3 | AM4: M301 | AN4: M1 | AO4: R303 | AP4: S401 | AQ4: D401 | AR4: H2SO4_storage | AS4: BT | AT4: - | AU4: M201 | AV4: M203 | AW4: M203 | AX4: T201 | AY4: M201 | AZ4: M203 | BA4: R201 | BB4: M204 | BC4: P201 | BD4: T202 | BE4: F201 | BF4: M204 | BG4: T203 | BH4: H201 | BI4: M205 | BJ4: T203 | BK4: P202 | BL4: H301 | BM4: R301 | BN4: S301 | BO4: S302 | BP4: R302 | BQ4: M304 | BR4: T301 | BS4: R303 | BT4: M304 | BU4: M401 | BV4: T302 | BW4: D401 | BX4: M401 | BY4: M402 | BZ4: H401 | CA4: P402 | CB4: H401 | CC4: D402 | CD4: D403 | CE4: H402 | CF4: P403 | CG4: U401 | CH4: M402 | CI4: H403 | CJ4: T701 | CK4: P701 | CL4: M701 | CM4: P702 | CN4: M701 | CO4: T703 | CP4: S401 | CQ4: M1 | CR4: M601 | CS4: WWTC | CT4: R601 | CU4: M602 | CV4: M603 | CW4: M602 | CX4: R602 | CY4: S601 | CZ4: S604 | DA4: S602 | DB4: M604 | DC4: M603 | DD4: S603 | DE4: M604 | DF4: - | DG4: - | DH4: - | DI4: PWC | DJ4: PWC | DK4: - | DL4: - | DM4: -
A5: Phase | B5: liquid | C5: liquid | D5: liquid | E5: liquid | F5: liquid | G5: liquid | H5: liquid | I5: liquid | J5: liquid | K5: liquid | L5: gas | M5: gas | N5: liquid | O5: liquid | P5: liquid | Q5: liquid | R5: gas | S5: liquid | T5: liquid | U5: liquid | V5: liquid | W5: liquid | X5: liquid | Y5: gas | Z5: liquid | AA5: gas | AB5: liquid | AC5: gas | AD5: liquid | AE5: liquid | AF5: liquid | AG5: gas | AH5: liquid | AI5: liquid | AJ5: gas | AK5: liquid | AL5: liquid | AM5: liquid | AN5: liquid | AO5: liquid | AP5: liquid | AQ5: liquid | AR5: liquid | AS5: liquid | AT5: gas | AU5: liquid | AV5: liquid | AW5: liquid | AX5: liquid | AY5: liquid | AZ5: liquid | BA5: liquid | BB5: gas | BC5: liquid | BD5: liquid | BE5: liquid | BF5: gas | BG5: liquid | BH5: gas | BI5: liquid | BJ5: liquid | BK5: liquid | BL5: liquid | BM5: liquid | BN5: liquid | BO5: liquid | BP5: liquid | BQ5: gas | BR5: liquid | BS5: liquid | BT5: gas | BU5: liquid | BV5: liquid | BW5: gas | BX5: liquid | BY5: gas | BZ5: liquid | CA5: liquid | CB5: liquid | CC5: liquid | CD5: gas | CE5: gas | CF5: liquid | CG5: gas | CH5: gas | CI5: gas | CJ5: liquid | CK5: liquid | CL5: liquid | CM5: liquid | CN5: liquid | CO5: liquid | CP5: liquid | CQ5: liquid | CR5: liquid | CS5: liquid | CT5: liquid | CU5: liquid | CV5: liquid | CW5: liquid | CX5: liquid | CY5: liquid | CZ5: liquid | DA5: liquid | DB5: liquid | DC5: liquid | DD5: liquid | DE5: liquid | DF5: liquid | DG5: liquid | DH5: liquid | DI5: liquid | DJ5: liquid | DK5: liquid | DL5: liquid | DM5: liquid
A6: T (K) | B6: 298.15 | C6: 298.15 | D6: 298.15 | E6: 298.15 | F6: 298.15 | G6: 298.15 | H6: 298.15 | I6: 298.15 | J6: 307.68625 | K6: 298.15 | L6: 298.15 | M6: 298.15 | N6: 298.15 | O6: 368.15 | P6: 298.15 | Q6: 304.68099 | R6: 307.65177 | S6: 298.15 | T6: 298.15 | U6: 307.68625 | V6: 298.15 | W6: 298.15 | X6: 298.15 | Y6: 397.76608 | Z6: 339.26085 | AA6: 298.15 | AB6: 298.15 | AC6: 307.65177 | AD6: 298.15 | AE6: 298.15 | AF6: 298.15 | AG6: 288.70556 | AH6: 298.15 | AI6: 374.47896 | AJ6: 541.15 | AK6: 373.15 | AL6: 386.84603 | AM6: 298.15 | AN6: 307.80337 | AO6: 321.15 | AP6: 314.68099 | AQ6: 298.15 | AR6: 294.15 | AS6: 313.11763 | AT6: 304.50268 | AU6: 368.15 | AV6: 368.15 | AW6: 298.15 | AX6: 294.15 | AY6: 294.15 | AZ6: 366.42721 | BA6: 431.15 | BB6: 403.15 | BC6: 403.15 | BD6: 403.15 | BE6: 403.15 | BF6: 373.26524 | BG6: 373.26524 | BH6: 387.95777 | BI6: 298.15 | BJ6: 367.62321 | BK6: 374.47896 | BL6: 364.02211 | BM6: 321.15 | BN6: 298.15 | BO6: 298.15 | BP6: 305.15 | BQ6: 298.15 | BR6: 305.15 | BS6: 305.15 | BT6: 305.15 | BU6: 305.15 | BV6: 304.68099 | BW6: 304.50268 | BX6: 298.15 | BY6: 386.1424 | BZ6: 304.68099 | CA6: 395.32172 | CB6: 395.32172 | CC6: 378.33379 | CD6: 386.39736 | CE6: 363.91613 | CF6: 386.84603 | CG6: 388.15 | CH6: 388.15 | CI6: 388.15 | CJ6: 340 | CK6: 340 | CL6: 340 | CM6: 298.15 | CN6: 298.15 | CO6: 339.26085 | CP6: 320.15 | CQ6: 314.681 | CR6: 314.681 | CS6: 319.03452 | CT6: 319.03452 | CU6: 307.65177 | CV6: 308.15 | CW6: 307.69207 | CX6: 307.68625 | CY6: 307.68625 | CZ6: 307.68625 | DA6: 307.68625 | DB6: 307.68625 | DC6: 307.68625 | DD6: 307.80337 | DE6: 307.80337 | DF6: 298.15 | DG6: 298.15 | DH6: 298.15 | DI6: 386.84603 | DJ6: 307.68625 | DK6: 298.15 | DL6: 298.15 | DM6: 298.15
A7: flow (kg/hr) | B7: 126.11728 | C7: 1290.7002 | D7: 215.11669 | E7: 1075.5835 | F7: 158.86522 | G7: 25.173949 | H7: 133.69127 | I7: 363.24939 | J7: 326567.17 | K7: 104229.16 | L7: 1275408.8 | M7: 10057.753 | N7: 1300.7129 | O7: 89212.883 | P7: 5736.4247 | Q7: 437719.81 | R7: 21157.182 | S7: 7689.1822 | T7: 0.4958241 | U7: 9523.0306 | V7: 4133.0899 | W7: 12672.617 | X7: 473.10115 | Y7: 1333842.2 | Z7: 21978.354 | AA7: 36736.643 | AB7: 8338.3328 | AC7: 21157.182 | AD7: 0 | AE7: 73288.396 | AF7: 7689.1822 | AG7: 0 | AH7: 83383.328 | AI7: 378390.45 | AJ7: 32610.978 | AK7: 27849.013 | AL7: 21256.472 | AM7: 39170.318 | AN7: 6703.4328 | AO7: 430233.39 | AP7: 394958.09 | AQ7: 26378.529 | AR7: 1925.9728 | AS7: 42870.893 | AT7: 20378.78 | AU7: 23450.964 | AV7: 153579.54 | AW7: 104229.16 | AX7: 1925.9728 | AY7: 1925.9728 | AZ7: 25376.937 | BA7: 315796.61 | BB7: 13666.128 | BC7: 302059.74 | BD7: 302059.74 | BE7: 302059.74 | BF7: 14182.884 | BG7: 287876.86 | BH7: 27849.013 | BI7: 1300.7129 | BJ7: 90513.596 | BK7: 378390.45 | BL7: 430233.39 | BM7: 430233.39 | BN7: 158.86522 | BO7: 1290.7002 | BP7: 43023.339 | BQ7: 1977.3729 | BR7: 41293.234 | BS7: 41293.234 | BT7: 18863.68 | BU7: 410879.01 | BV7: 437719.81 | BW7: 20841.053 | BX7: 26840.802 | BY7: 42761.725 | BZ7: 437719.81 | CA7: 394958.09 | CB7: 394958.09 | CC7: 437719.81 | CD7: 49071.363 | CE7: 27814.891 | CF7: 21256.472 | CG7: 27814.891 | CH7: 6309.6383 | CI7: 21505.253 | CJ7: 21505.253 | CK7: 21505.253 | CL7: 21505.253 | CM7: 473.10115 | CN7: 473.10115 | CO7: 21978.354 | CP7: 1 | CQ7: 36167.46 | CR7: 358791.63 | CS7: 386640.64 | CT7: 386640.64 | CU7: 338498.57 | CV7: 26984.891 | CW7: 1996420 | CX7: 2334774.6 | CY7: 2312228.8 | CZ7: 336090.21 | DA7: 1976138.6 | DB7: 1897093 | DC7: 79045.543 | DD7: 106030.43 | DE7: 99327.001 | DF7: 126.11728 | DG7: 83383.328 | DH7: 8338.3328 | DI7: 21256.472 | DJ7: 326567.17 | DK7: 48243.173 | DL7: 372868.66 | DM7: 0
A8: Composition [%]:
A9: Water | B9: 100 | C9: 0 | D9: 0 | E9: 0 | F9: 0 | G9: 0 | H9: 0 | I9: 49.304992 | J9: 100 | K9: 20.214798 | L9: 0 | M9: 0 | N9: 0 | O9: 100 | P9: 23.076923 | Q9: 83.791982 | R9: 3.1577538 | S9: 100 | T9: 0 | U9: 45.167239 | V9: 50 | W9: 95 | X9: 0 | Y9: 3.0639298 | Z9: 0.80639541 | AA9: 70.795461 | AB9: 100 | AC9: 3.1577538 | AD9: 0 | AE9: 100 | AF9: 100 | AG9: 0 | AH9: 0 | AI9: 76.928228 | AJ9: 100 | AK9: 97.953952 | AL9: 99.999 | AM9: 100 | AN9: 79 | AO9: 79.561091 | AP9: 87.437281 | AQ9: 100 | AR9: 6.7357513 | AS9: 41.879984 | AT9: 0 | AU9: 100 | AV9: 100 | AW9: 20.214798 | AX9: 6.7357513 | AY9: 6.7357513 | AZ9: 92.921746 | BA9: 73.097973 | BB9: 97.914716 | BC9: 71.215836 | BD9: 71.215836 | BE9: 71.215836 | BF9: 97.991758 | BG9: 69.896662 | BH9: 97.953952 | BI9: 0 | BJ9: 98.562964 | BK9: 76.928228 | BL9: 79.561091 | BM9: 79.561091 | BN9: 0 | BO9: 0 | BP9: 78.943361 | BQ9: 0 | BR9: 82.32902 | BS9: 82.32902 | BT9: 1.4627357 | BU9: 82.778541 | BV9: 83.791982 | BW9: 1.3239532 | BX9: 99.30573 | BY9: 50.123076 | BZ9: 83.791982 | CA9: 87.437281 | CB9: 87.437281 | CC9: 83.791982 | CD9: 48.132615 | CE9: 8.4957036 | CF9: 99.999 | CG9: 8.4957036 | CH9: 34.642846 | CI9: 0.82413557 | CJ9: 0.82413557 | CK9: 0.82413557 | CL9: 0.82413557 | CM9: 0 | CN9: 0 | CO9: 0.80639541 | CP9: 100 | CQ9: 35 | CR9: 92.723179 | CS9: 93.099942 | CT9: 93.099942 | CU9: 98.614884 | CV9: 94.438582 | CW9: 98.420872 | CX9: 98.448773 | CY9: 98.414744 | CZ9: 98.446328 | DA9: 98.409372 | DB9: 98.409372 | DC9: 98.409372 | DD9: 97.398801 | DE9: 98.640509 | DF9: 100 | DG9: 0 | DH9: 100 | DI9: 99.999 | DJ9: 100 | DK9: 100 | DL9: 100 | DM9: 0
A10: Ethanol | B10: 0 | C10: 0 | D10: 0 | E10: 0 | F10: 0 | G10: 0 | H10: 0 | I10: 0 | J10: 0 | K10: 0 | L10: 0 | M10: 0 | N10: 0 | O10: 0 | P10: 0 | Q10: 4.8702933 | R10: 3.2035969e-05 | S10: 0 | T10: 0 | U10: 1.5840589e-05 | V10: 0 | W10: 0 | X10: 0 | Y10: 0 | Z10: 96.979841 | AA10: 0 | AB10: 0 | AC10: 3.2035969e-05 | AD10: 0 | AE10: 0 | AF10: 0 | AG10: 0 | AH10: 0 | AI10: 0 | AJ10: 0 | AK10: 0 | AL10: 0.0010000075 | AM10: 0 | AN10: 2.01271e-05 | AO10: 0 | AP10: 0.00087438808 | AQ10: 0 | AR10: 0 | AS10: 0.00030232855 | AT10: 0 | AU10: 0 | AV10: 0 | AW10: 0 | AX10: 0 | AY10: 0 | AZ10: 0 | BA10: 0 | BB10: 0 | BC10: 0 | BD10: 0 | BE10: 0 | BF10: 0 | BG10: 0 | BH10: 0 | BI10: 0 | BJ10: 0 | BK10: 0 | BL10: 0 | BM10: 0 | BN10: 0 | BO10: 0 | BP10: 0 | BQ10: 0 | BR10: 5.0101768 | BS10: 5.0101768 | BT10: 0.96919271 | BU10: 5.1439506 | BV10: 4.8702933 | BW10: 0.87723693 | BX10: 0.68114736 | BY10: 49.845476 | BZ10: 4.8702933 | CA10: 0.00087438808 | CB10: 0.00087438808 | CC10: 4.8702933 | CD10: 51.839981 | CE10: 91.455949 | CF10: 0.0010000075 | CG10: 91.455949 | CH10: 65.357154 | CI10: 99.113332 | CJ10: 99.113332 | CK10: 99.113332 | CL10: 99.113332 | CM10: 0 | CN10: 0 | CO10: 96.979841 | CP10: 0 | CQ10: 0.00035463299 | CR10: 0.00092677879 | CS10: 0.00086002462 | CT10: 0.00086002462 | CU10: 8.0950548e-05 | CV10: 6.8460793e-05 | CW10: 1.3867018e-06 | CX10: 1.2922054e-05 | CY10: 5.2192212e-07 | CZ10: 4.4883908e-07 | DA10: 5.3435166e-07 | DB10: 5.3435166e-07 | DC10: 5.3435166e-07 | DD10: 1.7821724e-05 | DE10: 1.7666138e-05 | DF10: 0 | DG10: 0 | DH10: 0 | DI10: 0.0010000075 | DJ10: 0 | DK10: 0 | DL10: 0 | DM10: 0
A11: AceticAcid | B11: 0 | C11: 0 | D11: 0 | E11: 0 | F11: 0 | G11: 0 | H11: 0 | I11: 0 | J11: 0 | K11: 0 | L11: 0 | M11: 0 | N11: 0 | O11: 0 | P11: 0 | Q11: 0.28583834 | R11: 0.002488149 | S11: 0 | T11: 0 | U11: 0.0071784812 | V11: 0 | W11: 0 | X11: 0 | Y11: 0 | Z11: 0 | AA11: 0 | AB11: 0 | AC11: 0.002488149 | AD11: 0 | AE11: 0 | AF11: 0 | AG11: 0 | AH11: 0 | AI11: 0.33065607 | AJ11: 0 | AK11: 0.98649336 | AL11: 0 | AM11: 0 | AN11: 0.010232196 | AO11: 0.29081216 | AP11: 0.31678594 | AQ11: 0 | AR11: 0 | AS11: 0.1099917 | AT11: 0 | AU11: 0 | AV11: 0 | AW11: 0 | AX11: 0 | AY11: 0 | AZ11: 0 | BA11: 0 | BB11: 0.93345555 | BC11: 0.4629324 | BD11: 0.4629324 | BE11: 0.4629324 | BF11: 1.0375987 | BG11: 0.43462021 | BH11: 0.98649336 | BI11: 0 | BJ11: 0 | BK11: 0.33065607 | BL11: 0.29081216 | BM11: 0.29081216 | BN11: 0 | BO11: 0 | BP11: 0.29081216 | BQ11: 0 | BR11: 0.30299661 | BS11: 0.30299661 | BT11: 0.010429771 | BU11: 0.30403199 | BV11: 0.28583834 | BW11: 0.0094402074 | BX11: 0.0073300292 | BY11: 0 | BZ11: 0.28583834 | CA11: 0.31678578 | CB11: 0.31678578 | CC11: 0.28583834 | CD11: 0 | CE11: 0 | CF11: 0 | CG11: 0 | CH11: 0 | CI11: 0 | CJ11: 0 | CK11: 0 | CL11: 0 | CM11: 0 | CN11: 0 | CO11: 0 | CP11: 0 | CQ11: 0.12848156 | CR11: 0.33576681 | CS11: 0.38263744 | CT11: 0.38263744 | CU11: 0.036398173 | CV11: 0.034890447 | CW11: 0.00067693688 | CX11: 0.0058558883 | CY11: 0.00023651949 | CZ11: 0.00020340044 | DA11: 0.00024215218 | DB11: 0.00024215218 | DC11: 0.00024215218 | DD11: 0.0090601908 | DE11: 0.008981094 | DF11: 0 | DG11: 0 | DH11: 0 | DI11: 0 | DJ11: 0 | DK11: 0 | DL11: 0 | DM11: 0
A12: Furfural | B12: 0 | C12: 0 | D12: 0 | E12: 0 | F12: 0 | G12: 0 | H12: 0 | I12: 0 | J12: 0 | K12: 0 | L12: 0 | M12: 0 | N12: 0 | O12: 0 | P12: 0 | Q12: 0.070960472 | R12: 0.0038562983 | S12: 0 | T12: 0 | U12: 0.002867192 | V12: 0 | W12: 0 | X12: 0 | Y12: 0 | Z12: 0 | AA12: 0 | AB12: 0 | AC12: 0.0038562983 | AD12: 0 | AE12: 0 | AF12: 0 | AG12: 0 | AH12: 0 | AI12: 0.082086635 | AJ12: 0 | AK12: 1.0595546 | AL12: 0 | AM12: 0 | AN12: 0 | AO12: 0.072195232 | AP12: 0.07864342 | AQ12: 0 | AR12: 0 | AS12: 0.025872639 | AT12: 0 | AU12: 0 | AV12: 0 | AW12: 0 | AX12: 0 | AY12: 0 | AZ12: 0 | BA12: 0 | BB12: 1.1518283 | BC12: 0.14840546 | BD12: 0.14840546 | BE12: 0.14840546 | BF12: 0.97064286 | BG12: 0.10789613 | BH12: 1.0595546 | BI12: 0 | BJ12: 0 | BK12: 0.082086635 | BL12: 0.072195232 | BM12: 0.072195232 | BN12: 0 | BO12: 0 | BP12: 0.072195232 | BQ12: 0 | BR12: 0.075220069 | BS12: 0.075220069 | BT12: 0.0082379051 | BU12: 0.075217781 | BV12: 0.070960472 | BW12: 0.007456303 | BX12: 0.0057895888 | BY12: 0 | BZ12: 0.070960472 | CA12: 0.078643293 | CB12: 0.078643293 | CC12: 0.070960472 | CD12: 0 | CE12: 0 | CF12: 0 | CG12: 0 | CH12: 0 | CI12: 0 | CJ12: 0 | CK12: 0 | CL12: 0 | CM12: 0 | CN12: 0 | CO12: 0 | CP12: 0 | CQ12: 0.030667985 | CR12: 0.083479294 | CS12: 0.1537842 | CT12: 0.1537842 | CU12: 0.014523147 | CV12: 0.013106489 | CW12: 0.00027289232 | CX12: 0.0023389288 | CY12: 9.4469397e-05 | CZ12: 8.1241158e-05 | DA12: 9.671918e-05 | DB12: 9.671918e-05 | DC12: 9.671918e-05 | DD12: 0.0034077235 | DE12: 0.0036377058 | DF12: 0 | DG12: 0 | DH12: 0 | DI12: 0 | DJ12: 0 | DK12: 0 | DL12: 0 | DM12: 0
A13: Glycerol | B13: 0 | C13: 0 | D13: 0 | E13: 0 | F13: 0 | G13: 0 | H13: 0 | I13: 0 | J13: 0 | K13: 0 | L13: 0 | M13: 0 | N13: 0 | O13: 0 | P13: 0 | Q13: 0.038987214 | R13: 1.8587332e-08 | S13: 0 | T13: 0 | U13: 0.00079789801 | V13: 0 | W13: 0 | X13: 0 | Y13: 0 | Z13: 0 | AA13: 0 | AB13: 0 | AC13: 1.8587332e-08 | AD13: 0 | AE13: 0 | AF13: 0 | AG13: 0 | AH13: 0 | AI13: 0 | AJ13: 0 | AK13: 0 | AL13: 0 | AM13: 0 | AN13: 0.0018433536 | AO13: 0 | AP13: 0.043208321 | AQ13: 0 | AR13: 0 | AS13: 0.015072431 | AT13: 0 | AU13: 0 | AV13: 0 | AW13: 0 | AX13: 0 | AY13: 0 | AZ13: 0 | BA13: 0 | BB13: 0 | BC13: 0 | BD13: 0 | BE13: 0 | BF13: 0 | BG13: 0 | BH13: 0 | BI13: 0 | BJ13: 0 | BK13: 0 | BL13: 0 | BM13: 0 | BN13: 0 | BO13: 0 | BP13: 0 | BQ13: 0 | BR13: 0.042199196 | BS13: 0.042199196 | BT13: 7.4257183e-08 | BU13: 0.041534063 | BV13: 0.038987214 | BW13: 6.7211755e-08 | BX13: 5.218785e-08 | BY13: 0 | BZ13: 0.038987214 | CA13: 0.043208321 | CB13: 0.043208321 | CC13: 0.038987214 | CD13: 0 | CE13: 0 | CF13: 0 | CG13: 0 | CH13: 0 | CI13: 0 | CJ13: 0 | CK13: 0 | CL13: 0 | CM13: 0 | CN13: 0 | CO13: 0 | CP13: 0 | CQ13: 0.017524365 | CR13: 0.045797234 | CS13: 0.042498544 | CT13: 0.042498544 | CU13: 0.0040465596 | CV13: 0.0040428082 | CW13: 7.5097821e-05 | CX13: 0.00065089 | CY13: 2.6289465e-05 | CZ13: 2.2608237e-05 | DA13: 2.6915547e-05 | DB13: 2.6915547e-05 | DC13: 2.6915547e-05 | DD13: 0.0010489658 | DE13: 0.00099535369 | DF13: 0 | DG13: 0 | DH13: 0 | DI13: 0 | DJ13: 0 | DK13: 0 | DL13: 0 | DM13: 0
A14: H2SO4 | B14: 0 | C14: 0 | D14: 0 | E14: 0 | F14: 0 | G14: 0 | H14: 0 | I14: 0 | J14: 0 | K14: 0 | L14: 0 | M14: 0 | N14: 0 | O14: 0 | P14: 0 | Q14: 0 | R14: 0 | S14: 0 | T14: 0 | U14: 0 | V14: 0 | W14: 0 | X14: 0 | Y14: 0 | Z14: 0 | AA14: 0 | AB14: 0 | AC14: 0 | AD14: 0 | AE14: 0 | AF14: 0 | AG14: 0 | AH14: 0 | AI14: 0 | AJ14: 0 | AK14: 0 | AL14: 0 | AM14: 0 | AN14: 0 | AO14: 0 | AP14: 0 | AQ14: 0 | AR14: 93.264249 | AS14: 0 | AT14: 0 | AU14: 0 | AV14: 0 | AW14: 0 | AX14: 93.264249 | AY14: 93.264249 | AZ14: 7.078254 | BA14: 0.56879775 | BB14: 0 | BC14: 0.59466516 | BD14: 0.59466516 | BE14: 0.59466516 | BF14: 0 | BG14: 0.62396264 | BH14: 0 | BI14: 0 | BJ14: 0 | BK14: 0 | BL14: 0 | BM14: 0 | BN14: 0 | BO14: 0 | BP14: 0 | BQ14: 0 | BR14: 0 | BS14: 0 | BT14: 0 | BU14: 0 | BV14: 0 | BW14: 0 | BX14: 0 | BY14: 0 | BZ14: 0 | CA14: 0 | CB14: 0 | CC14: 0 | CD14: 0 | CE14: 0 | CF14: 0 | CG14: 0 | CH14: 0 | CI14: 0 | CJ14: 0 | CK14: 0 | CL14: 0 | CM14: 0 | CN14: 0 | CO14: 0 | CP14: 0 | CQ14: 0 | CR14: 0 | CS14: 0 | CT14: 0 | CU14: 0 | CV14: 0 | CW14: 0 | CX14: 0 | CY14: 0 | CZ14: 0 | DA14: 0 | DB14: 0 | DC14: 0 | DD14: 0 | DE14: 0 | DF14: 0 | DG14: 0 | DH14: 0 | DI14: 0 | DJ14: 0 | DK14: 0 | DL14: 0 | DM14: 0
A15: NH3 | B15: 0 | C15: 0 | D15: 0 | E15: 0 | F15: 0 | G15: 0 | H15: 0 | I15: 0 | J15: 0 | K15: 0 | L15: 0 | M15: 0 | N15: 1.309322 | O15: 0 | P15: 0 | Q15: 0.0030722263 | R15: 0 | S15: 0 | T15: 0 | U15: 0 | V15: 0 | W15: 0 | X15: 0 | Y15: 0 | Z15: 0.061186307 | AA15: 0 | AB15: 0 | AC15: 0 | AD15: 0 | AE15: 0 | AF15: 0 | AG15: 0 | AH15: 0 | AI15: 0.0045007795 | AJ15: 0 | AK15: 0 | AL15: 0 | AM15: 0 | AN15: 0 | AO15: 0.0039584376 | AP15: 0 | AQ15: 0 | AR15: 0 | AS15: 0 | AT15: 0.01758092 | AU15: 0 | AV15: 0 | AW15: 0 | AX15: 0 | AY15: 0 | AZ15: 0 | BA15: 0 | BB15: 0 | BC15: 0 | BD15: 0 | BE15: 0 | BF15: 0 | BG15: 0 | BH15: 0 | BI15: 1.309322 | BJ15: 0.018815428 | BK15: 0.0045007795 | BL15: 0.0039584376 | BM15: 0.0039584376 | BN15: 0 | BO15: 0 | BP15: 0.0039584376 | BQ15: 0 | BR15: 0.0041242883 | BS15: 0.0041242883 | BT15: 0.01899299 | BU15: 0.0032729204 | BV15: 0.0030722263 | BW15: 0.017190959 | BX15: 0 | BY15: 0.031448084 | BZ15: 0.0030722263 | CA15: 0 | CB15: 0 | CC15: 0.0030722263 | CD15: 0.027404462 | CE15: 0.04834728 | CF15: 0 | CG15: 0.04834728 | CH15: 0 | CI15: 0.062532365 | CJ15: 0.062532365 | CK15: 0.062532365 | CL15: 0.062532365 | CM15: 0 | CN15: 0 | CO15: 0.061186307 | CP15: 0 | CQ15: 0 | CR15: 0 | CS15: 0 | CT15: 0 | CU15: 0 | CV15: 0 | CW15: 0 | CX15: 0 | CY15: 0 | CZ15: 0 | DA15: 0 | DB15: 0 | DC15: 0 | DD15: 0 | DE15: 0 | DF15: 0 | DG15: 0 | DH15: 0 | DI15: 0 | DJ15: 0 | DK15: 0 | DL15: 0 | DM15: 0
A16: LacticAcid | B16: 0 | C16: 0 | D16: 0 | E16: 0 | F16: 0 | G16: 0 | H16: 0 | I16: 0 | J16: 0 | K16: 0 | L16: 0 | M16: 0 | N16: 0 | O16: 0 | P16: 0 | Q16: 0.37821793 | R16: 1.0719842e-06 | S16: 0 | T16: 0 | U16: 0.0090033867 | V16: 0 | W16: 0 | X16: 0 | Y16: 0 | Z16: 0 | AA16: 0 | AB16: 0 | AC16: 1.0719842e-06 | AD16: 0 | AE16: 0 | AF16: 0 | AG16: 0 | AH16: 0 | AI16: 0 | AJ16: 0 | AK16: 0 | AL16: 0 | AM16: 0 | AN16: 0.010049346 | AO16: 0 | AP16: 0.41916722 | AQ16: 0 | AR16: 0 | AS16: 0.145496 | AT16: 0 | AU16: 0 | AV16: 0 | AW16: 0 | AX16: 0 | AY16: 0 | AZ16: 0 | BA16: 0 | BB16: 0 | BC16: 0 | BD16: 0 | BE16: 0 | BF16: 0 | BG16: 0 | BH16: 0 | BI16: 0 | BJ16: 0 | BK16: 0 | BL16: 0 | BM16: 0 | BN16: 0 | BO16: 0 | BP16: 0 | BQ16: 0 | BR16: 0 | BS16: 0 | BT16: 4.4778945e-06 | BU16: 0.40292493 | BV16: 0.37821793 | BW16: 4.0530375e-06 | BX16: 3.1470584e-06 | BY16: 0 | BZ16: 0.37821793 | CA16: 0.41916722 | CB16: 0.41916722 | CC16: 0.37821793 | CD16: 0 | CE16: 0 | CF16: 0 | CG16: 0 | CH16: 0 | CI16: 0 | CJ16: 0 | CK16: 0 | CL16: 0 | CM16: 0 | CN16: 0 | CO16: 0 | CP16: 0 | CQ16: 0.17060026 | CR16: 0.44422247 | CS16: 0.41222595 | CT16: 0.41222595 | CU16: 0.039374793 | CV16: 0.037656765 | CW16: 0.00072848706 | CX16: 0.0063315222 | CY16: 0.00025573035 | CZ16: 0.00025510868 | DA16: 0.00025583609 | DB16: 0.00025583609 | DC16: 0.00025583609 | DD16: 0.009774424 | DE16: 0.0097558699 | DF16: 0 | DG16: 0 | DH16: 0 | DI16: 0 | DJ16: 0 | DK16: 0 | DL16: 0 | DM16: 0
A17: SuccinicAcid | B17: 0 | C17: 0 | D17: 0 | E17: 0 | F17: 0 | G17: 0 | H17: 0 | I17: 0 | J17: 0 | K17: 0 | L17: 0 | M17: 0 | N17: 0 | O17: 0 | P17: 0 | Q17: 0.097281158 | R17: 3.7400776e-09 | S17: 0 | T17: 0 | U17: 0.001990921 | V17: 0 | W17: 0 | X17: 0 | Y17: 0 | Z17: 0 | AA17: 0 | AB17: 0 | AC17: 3.7400776e-09 | AD17: 0 | AE17: 0 | AF17: 0 | AG17: 0 | AH17: 0 | AI17: 0 | AJ17: 0 | AK17: 0 | AL17: 0 | AM17: 0 | AN17: 0.0045995485 | AO17: 0 | AP17: 0.10781369 | AQ17: 0 | AR17: 0 | AS17: 0.037608831 | AT17: 0 | AU17: 0 | AV17: 0 | AW17: 0 | AX17: 0 | AY17: 0 | AZ17: 0 | BA17: 0 | BB17: 0 | BC17: 0 | BD17: 0 | BE17: 0 | BF17: 0 | BG17: 0 | BH17: 0 | BI17: 0 | BJ17: 0 | BK17: 0 | BL17: 0 | BM17: 0 | BN17: 0 | BO17: 0 | BP17: 0 | BQ17: 0 | BR17: 0.10520857 | BS17: 0.10520857 | BT17: 1.5461659e-08 | BU17: 0.10363608 | BV17: 0.097281158 | BW17: 1.3994677e-08 | BX17: 1.0866434e-08 | BY17: 0 | BZ17: 0.097281158 | CA17: 0.10781369 | CB17: 0.10781369 | CC17: 0.097281158 | CD17: 0 | CE17: 0 | CF17: 0 | CG17: 0 | CH17: 0 | CI17: 0 | CJ17: 0 | CK17: 0 | CL17: 0 | CM17: 0 | CN17: 0 | CO17: 0 | CP17: 0 | CQ17: 0.043726914 | CR17: 0.11427357 | CS17: 0.10604265 | CT17: 0.10604265 | CU17: 0.010097005 | CV17: 0.010087643 | CW17: 0.00018738461 | CX17: 0.0016241055 | CY17: 6.5597666e-05 | CZ17: 5.641224e-05 | DA17: 6.715987e-05 | DB17: 6.715987e-05 | DC17: 6.715987e-05 | DD17: 0.0026173866 | DE17: 0.0024836134 | DF17: 0 | DG17: 0 | DH17: 0 | DI17: 0 | DJ17: 0 | DK17: 0 | DL17: 0 | DM17: 0
A18: P4O10 | B18: 0 | C18: 0 | D18: 0 | E18: 0 | F18: 0 | G18: 0 | H18: 0 | I18: 0 | J18: 0 | K18: 0 | L18: 0 | M18: 0 | N18: 0 | O18: 0 | P18: 0 | Q18: 0 | R18: 0 | S18: 0 | T18: 0 | U18: 0 | V18: 0 | W18: 0 | X18: 0 | Y18: 0.0003288154 | Z18: 0 | AA18: 0 | AB18: 0 | AC18: 0 | AD18: 0 | AE18: 0 | AF18: 0 | AG18: 0 | AH18: 0 | AI18: 0 | AJ18: 0 | AK18: 0 | AL18: 0 | AM18: 0 | AN18: 0 | AO18: 0 | AP18: 0 | AQ18: 0 | AR18: 0 | AS18: 0 | AT18: 0 | AU18: 0 | AV18: 0 | AW18: 0 | AX18: 0 | AY18: 0 | AZ18: 0 | BA18: 0 | BB18: 0 | BC18: 0 | BD18: 0 | BE18: 0 | BF18: 0 | BG18: 0 | BH18: 0 | BI18: 0 | BJ18: 0 | BK18: 0 | BL18: 0 | BM18: 0 | BN18: 0 | BO18: 0 | BP18: 0 | BQ18: 0 | BR18: 0 | BS18: 0 | BT18: 0 | BU18: 0 | BV18: 0 | BW18: 0 | BX18: 0 | BY18: 0 | BZ18: 0 | CA18: 0 | CB18: 0 | CC18: 0 | CD18: 0 | CE18: 0 | CF18: 0 | CG18: 0 | CH18: 0 | CI18: 0 | CJ18: 0 | CK18: 0 | CL18: 0 | CM18: 0 | CN18: 0 | CO18: 0 | CP18: 0 | CQ18: 0 | CR18: 0 | CS18: 0 | CT18: 0 | CU18: 0 | CV18: 0 | CW18: 0 | CX18: 0 | CY18: 0 | CZ18: 0 | DA18: 0 | DB18: 0 | DC18: 0 | DD18: 0 | DE18: 0 | DF18: 0 | DG18: 0 | DH18: 0 | DI18: 0 | DJ18: 0 | DK18: 0 | DL18: 0 | DM18: 0
A19: Lime | B19: 0 | C19: 0 | D19: 0 | E19: 0 | F19: 0 | G19: 0 | H19: 0 | I19: 50.695008 | J19: 0 | K19: 0 | L19: 0 | M19: 0 | N19: 0 | O19: 0 | P19: 0 | Q19: 0 | R19: 0 | S19: 0 | T19: 0 | U19: 0 | V19: 0 | W19: 0 | X19: 0 | Y19: 0 | Z19: 0 | AA19: 0 | AB19: 0 | AC19: 0 | AD19: 0 | AE19: 0 | AF19: 0 | AG19: 0 | AH19: 0 | AI19: 0 | AJ19: 0 | AK19: 0 | AL19: 0 | AM19: 0 | AN19: 0 | AO19: 0 | AP19: 0 | AQ19: 0 | AR19: 0 | AS19: 0 | AT19: 0 | AU19: 0 | AV19: 0 | AW19: 0 | AX19: 0 | AY19: 0 | AZ19: 0 | BA19: 0 | BB19: 0 | BC19: 0 | BD19: 0 | BE19: 0 | BF19: 0 | BG19: 0 | BH19: 0 | BI19: 0 | BJ19: 0 | BK19: 0 | BL19: 0 | BM19: 0 | BN19: 0 | BO19: 0 | BP19: 0 | BQ19: 0 | BR19: 0 | BS19: 0 | BT19: 0 | BU19: 0 | BV19: 0 | BW19: 0 | BX19: 0 | BY19: 0 | BZ19: 0 | CA19: 0 | CB19: 0 | CC19: 0 | CD19: 0 | CE19: 0 | CF19: 0 | CG19: 0 | CH19: 0 | CI19: 0 | CJ19: 0 | CK19: 0 | CL19: 0 | CM19: 0 | CN19: 0 | CO19: 0 | CP19: 0 | CQ19: 0 | CR19: 0 | CS19: 0 | CT19: 0 | CU19: 0 | CV19: 0 | CW19: 0 | CX19: 0 | CY19: 0 | CZ19: 0 | DA19: 0 | DB19: 0 | DC19: 0 | DD19: 0 | DE19: 0 | DF19: 0 | DG19: 0 | DH19: 0 | DI19: 0 | DJ19: 0 | DK19: 0 | DL19: 0 | DM19: 0
A20: HNO3 | B20: 0 | C20: 0 | D20: 0 | E20: 0 | F20: 0 | G20: 0 | H20: 0 | I20: 0 | J20: 0 | K20: 0 | L20: 0 | M20: 0 | N20: 0 | O20: 0 | P20: 0 | Q20: 0 | R20: 0 | S20: 0 | T20: 0 | U20: 0 | V20: 0 | W20: 0 | X20: 0 | Y20: 0 | Z20: 0 | AA20: 0 | AB20: 0 | AC20: 0 | AD20: 0 | AE20: 0 | AF20: 0 | AG20: 0 | AH20: 0 | AI20: 0 | AJ20: 0 | AK20: 0 | AL20: 0 | AM20: 0 | AN20: 0 | AO20: 0 | AP20: 0 | AQ20: 0 | AR20: 0 | AS20: 0 | AT20: 0 | AU20: 0 | AV20: 0 | AW20: 0 | AX20: 0 | AY20: 0 | AZ20: 0 | BA20: 0 | BB20: 0 | BC20: 0 | BD20: 0 | BE20: 0 | BF20: 0 | BG20: 0 | BH20: 0 | BI20: 0 | BJ20: 0 | BK20: 0 | BL20: 0 | BM20: 0 | BN20: 0 | BO20: 0 | BP20: 0 | BQ20: 0 | BR20: 0 | BS20: 0 | BT20: 0 | BU20: 0 | BV20: 0 | BW20: 0 | BX20: 0 | BY20: 0 | BZ20: 0 | CA20: 0 | CB20: 0 | CC20: 0 | CD20: 0 | CE20: 0 | CF20: 0 | CG20: 0 | CH20: 0 | CI20: 0 | CJ20: 0 | CK20: 0 | CL20: 0 | CM20: 0 | CN20: 0 | CO20: 0 | CP20: 0 | CQ20: 0 | CR20: 0 | CS20: 0 | CT20: 0 | CU20: 0 | CV20: 0 | CW20: 0 | CX20: 0 | CY20: 0 | CZ20: 0 | DA20: 0 | DB20: 0 | DC20: 0 | DD20: 0 | DE20: 0 | DF20: 0 | DG20: 0 | DH20: 0 | DI20: 0 | DJ20: 0 | DK20: 0 | DL20: 0 | DM20: 0
... A74: Cellulase | B74: 0 | C74: 0 | D74: 0 | E74: 0 | F74: 0 | G74: 0 | H74: 0 | I74: 0 | J74: 0 | K74: 0 | L74: 0 | M74: 0 | N74: 0 | O74: 0 | P74: 0 | Q74: 0.14475717 | R74: 0 | S74: 0 | T74: 0 | U74: 0.0034459151 | V74: 0 | W74: 5 | X74: 0 | Y74: 0 | Z74: 0 | AA74: 0 | AB74: 0 | AC74: 0 | AD74: 0 | AE74: 0 | AF74: 0 | AG74: 0 | AH74: 0 | AI74: 0 | AJ74: 0 | AK74: 0 | AL74: 0 | AM74: 0 | AN74: 0.0038462366 | AO74: 0.14727607 | AP74: 0.16042989 | AQ74: 0 | AR74: 0 | AS74: 0.055686386 | AT74: 0 | AU74: 0 | AV74: 0 | AW74: 0 | AX74: 0 | AY74: 0 | AZ74: 0 | BA74: 0 | BB74: 0 | BC74: 0 | BD74: 0 | BE74: 0 | BF74: 0 | BG74: 0 | BH74: 0 | BI74: 0 | BJ74: 0 | BK74: 0 | BL74: 0.14727607 | BM74: 0.14727607 | BN74: 0 | BO74: 0 | BP74: 0.14727607 | BQ74: 0 | BR74: 0.15344665 | BS74: 0.15344665 | BT74: 0 | BU74: 0.15421348 | BV74: 0.14475717 | BW74: 0 | BX74: 0 | BY74: 0 | BZ74: 0.14475717 | CA74: 0.16042989 | CB74: 0.16042989 | CC74: 0.14475717 | CD74: 0 | CE74: 0 | CF74: 0 | CG74: 0 | CH74: 0 | CI74: 0 | CJ74: 0 | CK74: 0 | CL74: 0 | CM74: 0 | CN74: 0 | CO74: 0 | CP74: 0 | CQ74: 0.065294662 | CR74: 0.17001941 | CS74: 0.15777322 | CT74: 0.15777322 | CU74: 0.01507013 | CV74: 0.014412562 | CW74: 0.0002788176 | CX74: 0.0024232979 | CY74: 9.7877067e-05 | CZ74: 9.7639129e-05 | DA74: 9.7917534e-05 | DB74: 9.7917534e-05 | DC74: 9.7917534e-05 | DD74: 0.0037410143 | DE74: 0.003733913 | DF74: 0 | DG74: 0 | DH74: 0 | DI74: 0 | DJ74: 0 | DK74: 0 | DL74: 0 | DM74: 0
B77: cooling_tower_blowdown | C77: cooling_tower_chemicals | D77: cooling_tower_evaporation | E77: cooling_tower_makeup_water | F77: recirculated_chilled_water
A78: Source | B78: CT | C78: - | D78: CT | E78: - | F78: -
A79: Sink | B79: - | C79: CT | D79: - | E79: CT | F79: CWP
A80: Phase | B80: liquid | C80: liquid | D80: gas | E80: liquid | F80: liquid
A81: T (K) | B81: 324.817 | C81: 305.372 | D81: 324.817 | E81: 305.372 | F81: 300.15
A82: flow (kg/hr) | B82: 3686.7264 | C82: 0.93020188 | D82: 36867.264 | E82: 40553.99 | F82: 538442.42
A83: Composition [%]:
A84: Water | B84: 100 | C84: 100 | D84: 100 | E84: 100 | F84: 100

Sheet Reactions
A2: R602-Aerobic digestion | B2: Stoichiometry (by mol) | C2: Reactant | D2: Conversion [%]
A3: 0 | B3: Ethanol + 2.31 O2 -> 2.31 Water + 1.54 CO2 + 0.454 WWTsludge | C3: Ethanol | D3: 96
A4: 1 | B4: AceticAcid + 1.54 O2 -> 1.54 Water + 1.54 CO2 + 0.592 WWTsludge | C4: AceticAcid | D4: 96
A5: 2 | B5: Furfural + 3.85 O2 -> 1.54 Water + 3.85 CO2 + 0.948 WWTsludge | C5: Furfural | D5: 96
A6: 3 | B6: Glycerol + 2.7 O2 -> 3.08 Water + 2.31 CO2 + 0.908 WWTsludge | C6: Glycerol | D6: 96
A7: 4 | B7: LacticAcid + 2.31 O2 -> 2.31 Water + 2.31 CO2 + 0.888 WWTsludge | C7: LacticAcid | D7: 96
A8: 5 | B8: SuccinicAcid + 2.7 O2 -> 2.31 Water + 3.08 CO2 + 1.16 WWTsludge | C8: SuccinicAcid | D8: 96
A9: 6 | B9: Denaturant + 9.64 O2 -> 6.94 Water + 6.17 CO2 + 1.13 WWTsludge | C9: Denaturant | D9: 96
A10: 7 | B10: AmmoniumAcetate + 2.12 O2 -> 2.7 Water + 0.385 N2 + 1.54 CO2 + 0.76 WWTsludge | C10: AmmoniumAcetate | D10: 96
A11: 8 | B11: Oil + 19.7 O2 -> 13.1 Water + 13.9 CO2 + 2.79 WWTsludge | C11: Oil | D11: 96
A12: 9 | B12: HMF + 4.62 O2 -> 2.31 Water + 4.62 CO2 + 1.24 WWTsludge | C12: HMF | D12: 96
A13: 10 | B13: 4.62 O2 + Glucose -> 4.62 Water + 4.62 CO2 + 1.78 WWTsludge | C13: Glucose | D13: 96
A14: 11 | B14: 3.85 O2 + Xylose -> 3.85 Water + 3.85 CO2 + 1.48 WWTsludge | C14: Xylose | D14: 96
... A34: 31 | B34: 0.923 O2 + Cellulase -> 0.613 Water + 0.0925 N2 + 0.00771 SO2 + 0.771 CO2 + 0.237 WWTsludge | C34: Cellulase | D34: 96
A37: R601-Anaerobic digestion | B37: Stoichiometry (by mol) | C37: Reactant | D37: Conversion [%]
A38: 0 | B38: Ethanol -> 0.746 CH4 + 0.717 CO2 + 0.109 WWTsludge | C38: Ethanol | D38: 91
A39: 1 | B39: AceticAcid -> 0.973 CH4 + 0.935 CO2 + 0.142 WWTsludge | C39: AceticAcid | D39: 91
A40: 2 | B40: Furfural -> 1.56 CH4 + 1.5 CO2 + 0.227 WWTsludge | C40: Furfural | D40: 91
A41: 3 | B41: Glycerol -> 1.49 CH4 + 1.43 CO2 + 0.218 WWTsludge | C41: Glycerol | D41: 91
A42: 4 | B42: LacticAcid -> 1.46 CH4 + 1.4 CO2 + 0.213 WWTsludge | C42: LacticAcid | D42: 91
A43: 5 | B43: SuccinicAcid -> 1.91 CH4 + 1.84 CO2 + 0.279 WWTsludge | C43: SuccinicAcid | D43: 91
A44: 6 | B44: Denaturant -> 1.85 CH4 + 1.78 CO2 + 0.27 WWTsludge | C44: Denaturant | D44: 91
A45: 7 | B45: AmmoniumAcetate -> 1.25 CH4 + 1.2 CO2 + 0.182 WWTsludge | C45: AmmoniumAcetate | D45: 91
A46: 8 | B46: Oil -> 4.58 CH4 + 4.4 CO2 + 0.668 WWTsludge | C46: Oil | D46: 91
A47: 9 | B47: HMF -> 2.04 CH4 + 1.96 CO2 + 0.298 WWTsludge | C47: HMF | D47: 91
A48: 10 | B48: Glucose -> 2.92 CH4 + 2.8 CO2 + 0.426 WWTsludge | C48: Glucose | D48: 91
A49: 11 | B49: Xylose -> 2.43 CH4 + 2.34 CO2 + 0.355 WWTsludge | C49: Xylose | D49: 91
... A69: 31 | B69: Cellulase -> 0.389 CH4 + 0.374 CO2 + 0.0568 WWTsludge | C69: Cellulase | D69: 91
A72: BT-Boiler turbogenerator | B72: Stoichiometry (by mol) | C72: Reactant | D72: Conversion [%]
A73: 0 | B73: Ethanol + 3 O2 -> 3 Water + 2 CO2 | C73: Ethanol | D73: 100
A74: 1 | B74: AceticAcid + 2 O2 -> 2 Water + 2 CO2 | C74: AceticAcid | D74: 100
A75: 2 | B75: Furfural + 5 O2 -> 2 Water + 5 CO2 | C75: Furfural | D75: 100
A76: 3 | B76: Glycerol + 3.5 O2 -> 4 Water + 3 CO2 | C76: Glycerol | D76: 100
A77: 4 | B77: H2SO4 -> Water + 0.5 O2 + SO2 | C77: H2SO4 | D77: 100
A78: 5 | B78: NH3 + 0.75 O2 -> 1.5 Water + 0.5 N2 | C78: NH3 | D78: 100
A79: 6 | B79: LacticAcid + 3 O2 -> 3 Water + 3 CO2 | C79: LacticAcid | D79: 100
A80: 7 | B80: SuccinicAcid + 3.5 O2 -> 3 Water + 4 CO2 | C80: SuccinicAcid | D80: 100
A81: 8 | B81: Lime -> Water + 0.5 O2 + 40.1 Ash | C81: Lime | D81: 100
A82: 9 | B82: HNO3 -> 0.5 Water + 0.5 N2 + 1.25 O2 | C82: HNO3 | D82: 100
A83: 10 | B83: NH4OH + 0.75 O2 -> 2.5 Water + 0.5 N2 | C83: NH4OH | D83: 100
...

Sheet Design requirements
A2: Air distribution package | C2: Units | D2: ADP
A3: Design | B3: Flow rate | C3: kg/hr | D3: 83383.328
A4: Purchase cost | B4: Plant air compressor | C4: USD | D4: 28848.924
B5: Instrument air dryer | C5: USD | D5: 16313.38
B6: Plant air receiver | C6: USD | D6: 17400.938
A9: Ammonia addition tank | C9: Units | D9: T203
A10: Design | B10: Flow rate | C10: kg/hr | D10: 378390.45
A11: Purchase cost | B11: Agitator | C11: USD | D11: 22862.425
B12: Tank | C12: USD | D12: 484811.93
A15: Ammonia mixer | C15: Units | D15: M205
A16: Design | B16: Flow rate | C16: kg/hr | D16: 90513.596
A17: Purchase cost | B17: Mixer | C17: USD | D17: 4121.0922
A20: Ammonia storage tank | C20: Units | D20: Ammonia_storage
A21: Design | B21: Flow rate | C21: kg/hr | D21: 1300.7129
A22: Purchase cost | B22: Tank | C22: USD | D22: 229344.66
A23: Temperature
A24: Pressure
A26: Beer tank | C26: Units | D26: T302
A27: Design | B27: Flow rate | C27: kg/hr | D27: 437719.81
A28: Purchase cost | B28: Agitator | C28: USD | D28: 75278.606
B29: Pump | C29: USD | D29: 29782.35
B30: Tank | C30: USD | D30: 704839.41
A33: Blowdown discharge pump | C33: Units | D33: P201
A34: Design | B34: Flow rate | C34: kg/hr | D34: 302059.74
A35: Purchase cost | B35: Pump | C35: USD | D35: 26812.246
A38: Boiler turbogenerator | C38: Units | D38: BT
A39: Design | B39: Work | C39: kW | D39: 49101.806
B40: Flow rate | C40: kg/hr | D40: 256306.07
B41: Ash disposal | C41: kg/hr | D41: 5736.4247
A42: Purchase cost | B42: Baghouse bags | C42: USD | D42: 631286.91
B43: Boiler | C43: USD | D43: 30688775
B44: Deaerator | C44: USD | D44: 330247.74
B45: Amine addition pkg | C45: USD | D45: 43311.179
B46: Hot process water softener system | C46: USD | D46: 84456.798
B47: Turbogenerator | C47: USD | D47: 10715412
A50: CIP Package | C50: Units | D50: CIP
A51: Design | B51: Flow rate | C51: kg/hr | D51: 126.11728
A52: Purchase cost | B52: CIP Package | C52: USD | D52: 694125.33
A55: CSLStorage tank | C55: Units | D55: CSL_storage
A56: Design | B56: Flow rate | C56: kg/hr | D56: 1290.7002
...

Sheet Sizing code
B2: Pressure vessel Sizing | G2: Storage tank sizing
B3: Inputs | C3: Units | D3: Values | G3: Inputs | H3: Units | I3: Values
B4: Temperature | C4: K | D4: 321 | G4: Volume | H4: gal
B5: Pressure | C5: Pa | D5: =101325*2 -> 202650 | G5: Length | H5: ft | I5: 12
B6: Volume | C6: m3 | D6: 300 | G6: Diameter | H6: ft | I6: 15
B7: Material | D7: SS304 | G7: Material | I7: A283 C | J7: https://www.inyoprocess.com/images/chem_appl/sulfuric%20acid%20properties.pdf
B8: Configuration | D8: Horizontal | G8: Specific gravity | I8: 1.83
B9: Corrosion | D9: N | G9: Corrosive Material | I9: Y
B10: Welding efficiency | D10: 0.85 | G10: Joint efficiency | I10: 0.85
B13: Outputs | C13: Units | D13: Value | E13: Ref | G13: Outputs | H13: Units | I13: Value
B14: Absolute P | C14: psia | D14: =D5/6892.79 -> 29.400286 | G14: Corrosion allowance | H14: in | I14: =IF(I9="Y", 0.125, 0) -> 0.125
B15: Gauge P | C15: psig | D15: =D14-14.7 -> 14.700286 | G15: Corrosion allowance | H15: mm | I15: =(I14/12)*0.3048*1000 -> 3.175
B16: Design P | C16: psig | D16: =IF(AND(D15>=0, D15<=5), 5, IF(AND(D15>10, D15<=1000), EXP((0.6068+0.9165*LN(D15))+(0.0015655*(LN(D15))^2)), IF(D15>1000, 1.1*D15, ""))) -> 21.791941 | E16: From [3] | G16: Product Design Stress (Sd) | H16: Mpa | I16: =IFERROR(_xlfn.XLOOKUP(I7,Data!$B:$B,Data!$D:$D,""),"") -> 137
B17: T | C17: F | D17: =((D4-273.15)*(9/5))+32 -> 118.13 | G17: Hydrostatic Test Stress (St) | H17: MPa | I17: =IFERROR(_xlfn.XLOOKUP(I7,Data!$B:$B,Data!$E:$E,""),"") -> 154
B18: Design T | C18: F | D18: =D17+50 -> 168.13 | E18: From [3] | G18: L/D | I18: =IF(ISBLANK(I4),(I5/I6),1) -> 0.8
B19: Aspect ratio | D19: =IF(D15=0, 1, IF(AND(D15>0, D15<250), 3, IF(AND(D15>=250, D15<500), 4, IF(D15>=500, 5, "")))) -> 3 | E19: From [1]: Procedure 2-16 | G19: Volume | H19: m3 | I19: =I4/264.172 -> 0
B20: Inside diameter | C20: m | D20: =((4*D6)/(D19*PI()))^(0.33) -> 4.9501726 | G20: Diameter | H20: m | I20: =IF(ISBLANK(I4),I6*0.3048,((4*I19)/(I18*PI()))^(0.33)) -> 4.572
B21: Inside diameter | C21: ft | D21: =D20/0.3048 -> 16.240724 | G21: Length | H21: m | I21: =IF(ISBLANK(I4),I5*0.3048,I20*I18) -> 3.6576
B22: Inside diameter | C22: in | D22: =D21*12 -> 194.88868 | G22: Design shell thickness | H22: mm | I22: =((4.9*I20*(I21-0.3)*I8)/I16)+I15 -> 4.1797587
B23: Tangent-to-tangent length | C23: m | D23: =D19*D20 -> 14.850518 | G23: Hydrostatic test shell thickness | H23: mm | I23: =(4.9*I20*(I21-0.3))/I17 -> 0.48843923
B24: Length | C24: ft | D24: =D23/0.3048 -> 48.722171 | G24: Shell thickness | H24: mm | I24: =MAX(I22:I23) -> 4.1797587 | J24: API 650 5.6.3 1-foot method
B25: Length | C25: in | D25: =D24*12 -> 584.66605 | G25: Shell thickness | H25: mm | I25: =IF(AND(I20>=0,I20<=15),5, IF(AND(I20>15,I20<=36),6, IF(AND(I20>36,I20<=60),8, IF(I20>60,10,"")))) -> 5 | J25: API 650 Minimum thickness 5.6.1.1
B26: Maximum Allowable Stress | C26: ksi | D26: =IF($D$7="","", IF($D$18>INDEX(Data!$G:$G, MATCH($D$7, Data!$B:$B, 0)),"Over max temp", INDEX(Data!$H:$L, MATCH($D$7, Data!$B:$B, 0), MATCH(MAX(100,MIN($D$18, INDEX(Data!$G:$G, MATCH($D$7, Data!$B:$B, 0)))),{100,300,500,700,900},1) ) )) -> 20 | G26: Shell thickness | H26: mm | I26: =MAX(I24:I25) -> 5
B27: Maximum Allowable Stress | C27: psi | D27: =D26*1000 -> 20000 | E27: From [2]. Table 14.2 | G27: Shell thickness | H27: m | I27: =I26/1000 -> 0.005
B28: Thickness preliminary | C28: in | D28: =(D16*D22)/((2*D27*D10)-(1.2*D16)) -> 0.12500799 | E28: From [3] Eq. 16.6 | G28: Surface area of shell | H28: m2 | I28: =(2*PI()*(I20/2)*I21)+(2*PI()*(I20/2)^2) -> 85.370076 | J28: Cylindrical shape
B29: Minimum thickness | D29: =IF(D28>=0.25, D28, LOOKUP(D21,{0,4,6,8,10},{0.25,0.3125,0.375,0.4375,0.5}) ) -> 0.5 | E29: From [3] | G29: Density of material | H29: lb/in3 | I29: 0.2833
B30: Load/earthquake thickness | D30: =(0.22*(D22+18)*(D25^2))/(D27*(D22^2)) -> 0.02107598 | E30: From [3] Eq. 16.62 | G30: Density of material | H30: lb/ft3 | I30: =I29*12^3 -> 489.5424
B31: Thickness | C31: in | D31: =IF(D8="Vertical", (D29+D29+D30)/2, D29 ) -> 0.5 | G31: Density of material | H31: lb/m3 | I31: =I30*(1/0.3048)^3 -> 17288.027
B32: Corrosion allowance | C32: mm | D32: =IF(AND(D7="CS",D9="N"),2,IF(AND(D7="CS",D9="Y"),4,3.175)) -> 3.175 | G32: Shell weight | H32: lb | I32: =I31*I28*I27 -> 7379.4008
B33: Corrosion allowance | C33: in | D33: =(D32/1000/0.3048)*12 -> 0.125 | G33: Shell weight | H33: kg | I33: =I32/2.2 -> 3354.2731
B34: Thickness | C34: in | D34: =D31+D33 -> 0.625 | G34: Roof thickness | H34: mm | I34: =I25 -> 5 | J34: Assuming same as shell thickness
B35: Vessel Thickness | C35: in | D35: =CEILING( D34, IF(AND(D34>=3/16, D34<=1/2), 1/16, IF(AND(D34>=1/2, D34<=2), 1/8, IF(AND(D34>2, D34<=3), 1/4, 1/4 ))) ) -> 0.625 | G35: Bottom thickness | H35: mm | I35: =I25 -> 5 | J35: Assuming same as shell thickness
B36: Material density | C36: lb/in3 | D36: =IF($D$7="","", INDEX(Data!$F:$F, MATCH($D$7, Data!$B:$B, 0))) -> 0.286 | G36: Surface area of roof | H36: m2 | I36: =(PI()*(I20)^2)/4 -> 16.417322 | J36: Cylindrical shape
B37: Material density | C37: lb/ft3 | D37: =D36*12^3 -> 494.208 | G37: Surface area of bottom | H37: m2 | I37: =(PI()*(I20)^2)/4 -> 16.417322 | J37: Cylindrical shape
B38: Weight | C38: lb | D38: =PI()*(D22+D35)*(D25+0.8*D22)*(D35*D36) -> 81309.876 | G38: Roof weight | H38: lb | I38: =I36*I34*0.001*I31 -> 1419.1155
B39: Weight with allowance | C39: lb | D39: =IF(AND(D38>=0,D38<=50000),D38*1.1, IF(AND(D38>50000,D38<=75000),D38*1.08, IF(AND(D38>75000,D38<=100000),D38*1.06, IF(D38>100000,1.05*D38,"")))) -> 86188.469 | E39: From [1]: Procedure 2-18 | G39: Bottom weight | H39: lb | I39: =I37*I35*0.001*I31 -> 1419.1155
B40: Vessel Weight | C40: kg | D40: =D39/2.2 -> 39176.577 | G40: Roof weight | H40: kg | I40: =I38/2.2 -> 645.05252
G41: Bottom weight | H41: kg | I41: =I39/2.2 -> 645.05252
G42: Total weight | H42: kg | I42: =I33+I40+I41 -> 4644.3781

Sheet Data
B2: Table 1. Maximum Allowable Stresses [1] and densities [2]
B3: Key | C3: Material | D3: Min tensile (ksi) | E3: Min yield (ksi) | F3: Density (lb/in3) | G3: Max. temp (°F) | H3: 100 | I3: 300 | J3: 500 | K3: 700 | L3: 900
B4: CS | C4: Carbon steel | D4: 45 | E4: 24 | F4: 0.2833 | G4: 900 | H4: 12.9 | I4: 12.9 | J4: 12.9 | K4: 11.5 | L4: 5.9
B5: A515 | C5: Killed carbon steel | D5: 60 | E5: 32 | F5: 0.2833 | G5: 1000 | H5: 17.1 | I5: 17.1 | J5: 17.1 | K5: 14.3 | L5: 5.9
B6: A387 | C6: Low-alloy steel 1¼ Cr, ½ Mo, Si | D6: 60 | E6: 30 | F6: 0.2833 | G6: 1200 | H6: 17.1 | I6: 16.6 | J6: 16.6 | K6: 16.6 | L6: 13.6
B7: SS410 | C7: Stainless steel 13 Cr | D7: 65 | E7: 30 | F7: 0.283 | G7: 1200 | H7: 18.6 | I7: 17.8 | J7: 17.2 | K7: 16.2 | L7: 12.3
B8: SS304 | C8: Stainless steel 18 Cr, 8 Ni | D8: 75 | E8: 30 | F8: 0.286 | G8: 1500 | H8: 20 | I8: 15 | J8: 12.9 | K8: 11.7 | L8: 10.8
B9: SS347 | C9: Stainless steel 18 Cr, 10 Ni, Cb | D9: 75 | E9: 30 | F9: 0.286 | G9: 1500 | H9: 20 | I9: 17.1 | J9: 15 | K9: 13.8 | L9: 13.4
B10: SS321 | C10: Stainless steel 18 Cr, 10 Ni, Ti | D10: 75 | E10: 30 | F10: 0.286 | G10: 1500 | H10: 20 | I10: 16.5 | J10: 14.3 | K10: 13 | L10: 12.3
B11: SS316 | C11: Stainless steel 16 Cr, 12 Ni, 2 Mo | D11: 75 | E11: 30 | F11: 0.286 | G11: 1500 | H11: 20 | I11: 15.6 | J11: 13.3 | K11: 12.1 | L11: 11.5
B14: Material | C14: Material2 | D14: Sd (Mpa) | E14: St (Mpa)
B15: A283 C | C15: A283 C | D15: 137 | E15: 154
B16: A285 C | C16: A285 C | D16: 137 | E16: 154
B17: A131 A, B | C17: A131 A, B | D17: 157 | E17: 171
B18: A516M, 485 | C18: A516M, 485 | D18: 173 | E18: 195
B19: SS304 | C19: SS304 | D19: 155 | E19: 186
B20: SS304L | C20: SS304L | D20: 145 | E20: 155
B21: SS316 | C21: SS316 | D21: 155 | E21: 186
B22: SS316L | C22: SS316L | D22: 155 | E22: 186

Sheet PV Sizing
B2: Table. Pretreatment Reactor (R201) | F2: Table. Continuous presaccharification (R301) | J2: Table. Saccharification and Co-Fermentation (R303) | N2: Table. Seed train (R302)
B3: Inputs | C3: Units | D3: Values | F3: Inputs | G3: Units | H3: Values | J3: Inputs | K3: Units | L3: Values | N3: Inputs | O3: Units | P3: Values
B4: Temperature | C4: K | D4: 431.15 | F4: Temperature | G4: K | H4: 321.15 | J4: Temperature | K4: K | L4: ='Stream table'!AO6 -> 321.15 | N4: Temperature | O4: K | P4: 305.15
B5: Pressure | C5: Pa | D5: 557288 | F5: Pressure | G5: Pa | H5: =101325 -> 101325 | J5: Pressure | K5: Pa | L5: =101325 -> 101325 | N5: Pressure | O5: Pa | P5: =101325 -> 101325
B6: Volume | C6: m3 | D6: ='Design requirements'!D215 -> 66.232282 | F6: Volume | G6: m3 | H6: ='Design requirements'!D68 -> 1350.4169 | J6: Volume | K6: m3 | L6: ='Design requirements'!D250 -> 4001.9475 | N6: Volume | O6: m3 | P6: =SUM('Design requirements'!D270:D274) -> 52.947372
B7: Material | D7: SS316 | F7: Material | H7: SS304 | J7: Material | L7: SS304 | N7: Material | P7: SS304
B8: Configuration | D8: Horizontal | F8: Configuration | H8: Horizontal | J8: Configuration | L8: Horizontal | N8: Configuration | P8: Horizontal
B9: Corrosion | D9: Y | F9: Corrosion | H9: Y | J9: Corrosion | L9: Y | N9: Corrosion | P9: Y
B10: Welding efficiency | D10: 0.85 | F10: Welding efficiency | H10: 0.85 | J10: Welding efficiency | L10: 0.85 | N10: Welding efficiency | P10: 0.85
B13: Outputs | C13: Units | D13: Value | F13: Outputs | G13: Units | H13: Value | J13: Outputs | K13: Units | L13: Value | N13: Outputs | O13: Units | P13: Value
B14: Absolute P | C14: psia | D14: =D5/6892.79 -> 80.85086 | F14: Absolute P | G14: psia | H14: =H5/6892.79 -> 14.700143 | J14: Absolute P | K14: psia | L14: =L5/6892.79 -> 14.700143 | N14: Absolute P | O14: psia | P14: =P5/6892.79 -> 14.700143
B15: Gauge P | C15: psig | D15: =D14-14.7 -> 66.15086 | F15: Gauge P | G15: psig | H15: =H14-14.7 -> 0.0001431931 | J15: Gauge P | K15: psig | L15: =L14-14.7 -> 0.0001431931 | N15: Gauge P | O15: psig | P15: =P14-14.7 -> 0.0001431931
B16: Design P | C16: psig | D16: =IF(AND(D15>=0, D15<=5), 5, IF(AND(D15>10, D15<=1000), EXP((0.6068+0.9165*LN(D15))+(0.0015655*(LN(D15))^2)), IF(D15>1000, 1.1*D15, ""))) -> 87.901826 | F16: Design P | G16: psig | H16: =IF(AND(H15>=0, H15<=5), 5, IF(AND(H15>10, H15<=1000), EXP((0.6068+0.9165*LN(H15))+(0.0015655*(LN(H15))^2)), IF(H15>1000, 1.1*H15, ""))) -> 5 | J16: Design P | K16: psig | L16: =IF(AND(L15>=0, L15<=5), 5, IF(AND(L15>10, L15<=1000), EXP((0.6068+0.9165*LN(L15))+(0.0015655*(LN(L15))^2)), IF(L15>1000, 1.1*L15, ""))) -> 5 | N16: Design P | O16: psig | P16: =IF(AND(P15>=0, P15<=5), 5, IF(AND(P15>10, P15<=1000), EXP((0.6068+0.9165*LN(P15))+(0.0015655*(LN(P15))^2)), IF(P15>1000, 1.1*P15, ""))) -> 5
B17: T | C17: F | D17: =((D4-273.15)*(9/5))+32 -> 316.4 | F17: T | G17: F | H17: =((H4-273.15)*(9/5))+32 -> 118.4 | J17: T | K17: F | L17: =((L4-273.15)*(9/5))+32 -> 118.4 | N17: T | O17: F | P17: =((P4-273.15)*(9/5))+32 -> 89.6
B18: Design T | C18: F | D18: =D17+50 -> 366.4 | F18: Design T | G18: F | H18: =H17+50 -> 168.4 | J18: Design T | K18: F | L18: =L17+50 -> 168.4 | N18: Design T | O18: F | P18: =P17+50 -> 139.6
B19: Aspect ratio | D19: =IF(D15=0, 1, IF(AND(D15>0, D15<250), 3, IF(AND(D15>=250, D15<500), 4, IF(D15>=500, 5, "")))) -> 3 | F19: Aspect ratio | H19: =IF(H15=0, 1, IF(AND(H15>0, H15<250), 3, IF(AND(H15>=250, H15<500), 4, IF(H15>=500, 5, "")))) -> 3 | J19: Aspect ratio | L19: =IF(L15=0, 1, IF(AND(L15>0, L15<250), 3, IF(AND(L15>=250, L15<500), 4, IF(L15>=500, 5, "")))) -> 3 | N19: Aspect ratio | P19: =IF(P15=0, 1, IF(AND(P15>0, P15<250), 3, IF(AND(P15>=250, P15<500), 4, IF(P15>=500, 5, "")))) -> 3
B20: Inside diameter | C20: m | D20: =((4*D6)/(D19*PI()))^(0.33) -> 3.0069301 | F20: Inside diameter | G20: m | H20: =((4*H6)/(H19*PI()))^(0.33) -> 8.1325122 | J20: Inside diameter | K20: m | L20: =((4*L6)/(L19*PI()))^(0.33) -> 11.639113 | N20: Inside diameter | O20: m | P20: =((4*P6)/(P19*PI()))^(0.33) -> 2.7927945
B21: Inside diameter | C21: ft | D21: =D20/0.3048 -> 9.8652562 | F21: Inside diameter | G21: ft | H21: =H20/0.3048 -> 26.68147 | J21: Inside diameter | K21: ft | L21: =L20/0.3048 -> 38.186066 | N21: Inside diameter | O21: ft | P21: =P20/0.3048 -> 9.1627116
B22: Inside diameter | C22: in | D22: =D21*12 -> 118.38307 | F22: Inside diameter | G22: in | H22: =H21*12 -> 320.17764 | J22: Inside diameter | K22: in | L22: =L21*12 -> 458.23279 | N22: Inside diameter | O22: in | P22: =P21*12 -> 109.95254
B23: Tangent-to-tangent length | C23: m | D23: =D19*D20 -> 9.0207903 | F23: Tangent-to-tangent length | G23: m | H23: =H19*H20 -> 24.397537 | J23: Tangent-to-tangent length | K23: m | L23: =L19*L20 -> 34.917339 | N23: Tangent-to-tangent length | O23: m | P23: =P19*P20 -> 8.3783835
B24: Length | C24: ft | D24: =D23/0.3048 -> 29.595769 | F24: Length | G24: ft | H24: =H23/0.3048 -> 80.044411 | J24: Length | K24: ft | L24: =L23/0.3048 -> 114.5582 | N24: Length | O24: ft | P24: =P23/0.3048 -> 27.488135
B25: Length | C25: in | D25: =D24*12 -> 355.14922 | F25: Length | G25: in | H25: =H24*12 -> 960.53293 | J25: Length | K25: in | L25: =L24*12 -> 1374.6984 | N25: Length | O25: in | P25: =P24*12 -> 329.85762
B26: Maximum Allowable Stress | C26: ksi | D26: =IF($D$7="","", IF($D$18>INDEX(Data!$G:$G, MATCH($D$7, Data!$B:$B, 0)),"Over max temp", INDEX(Data!$H:$L, MATCH($D$7, Data!$B:$B, 0), MATCH(MAX(100,MIN($D$18, INDEX(Data!$G:$G, MATCH($D$7, Data!$B:$B, 0)))),{100,300,500,700,900},1) ) )) -> 15.6 | F26: Maximum Allowable Stress | G26: ksi | H26: =IF($H$7="","", IF($H$18>INDEX(Data!$G:$G, MATCH($H$7, Data!$B:$B, 0)),"Over max temp", INDEX(Data!$H:$L, MATCH($H$7, Data!$B:$B, 0), MATCH(MAX(100,MIN($H$18, INDEX(Data!$G:$G, MATCH($H$7, Data!$B:$B, 0)))),{100,300,500,700,900},1) ) )) -> 20 | J26: Maximum Allowable Stress | K26: ksi | L26: =IF($L$7="","", IF($L$18>INDEX(Data!$G:$G, MATCH($L$7, Data!$B:$B, 0)),"Over max temp", INDEX(Data!$H:$L, MATCH($L$7, Data!$B:$B, 0), MATCH(MAX(100,MIN($L$18, INDEX(Data!$G:$G, MATCH($L$7, Data!$B:$B, 0)))),{100,300,500,700,900},1) ) )) -> 20 | N26: Maximum Allowable Stress | O26: ksi | P26: =IF($P$7="","", IF($P$18>INDEX(Data!$G:$G, MATCH($P$7, Data!$B:$B, 0)),"Over max temp", INDEX(Data!$H:$L, MATCH($P$7, Data!$B:$B, 0), MATCH(MAX(100,MIN($P$18, INDEX(Data!$G:$G, MATCH($P$7, Data!$B:$B, 0)))),{100,300,500,700,900},1) ) )) -> 20
B27: Maximum Allowable Stress | C27: psi | D27: =D26*1000 -> 15600 | F27: Maximum Allowable Stress | G27: psi | H27: =H26*1000 -> 20000 | J27: Maximum Allowable Stress | K27: psi | L27: =L26*1000 -> 20000 | N27: Maximum Allowable Stress | O27: psi | P27: =P26*1000 -> 20000
B28: Thickness preliminary | C28: in | D28: =(D16*D22)/((2*D27*D10)-(1.2*D16)) -> 0.39395338 | F28: Thickness preliminary | G28: in | H28: =(H16*H22)/((2*H27*H10)-(1.2*H16)) -> 0.047093258 | J28: Thickness preliminary | K28: in | L28: =(L16*L22)/((2*L27*L10)-(1.2*L16)) -> 0.067399069 | N28: Thickness preliminary | O28: in | P28: =(P16*P22)/((2*P27*P10)-(1.2*P16)) -> 0.016172345
B29: Minimum thickness | D29: =IF(D28>=0.25, D28, LOOKUP(D21,{0,4,6,8,10},{0.25,0.3125,0.375,0.4375,0.5}) ) -> 0.39395338 | F29: Minimum thickness | H29: =IF(H28>=0.25, H28, LOOKUP(H21,{0,4,6,8,10},{0.25,0.3125,0.375,0.4375,0.5}) ) -> 0.5 | J29: Minimum thickness | L29: =IF(L28>=0.25, L28, LOOKUP(L21,{0,4,6,8,10},{0.25,0.3125,0.375,0.4375,0.5}) ) -> 0.5 | N29: Minimum thickness | P29: =IF(P28>=0.25, P28, LOOKUP(P21,{0,4,6,8,10},{0.25,0.3125,0.375,0.4375,0.5}) ) -> 0.4375
B30: Load/earthquake thickness | D30: =(0.22*(D22+18)*(D25^2))/(D27*(D22^2)) -> 0.017310159 | F30: Load/earthquake thickness | H30: =(0.22*(H22+18)*(H25^2))/(H27*(H22^2)) -> 0.033479587 | J30: Load/earthquake thickness | L30: =(0.22*(L22+18)*(L25^2))/(L27*(L22^2)) -> 0.047147047 | N30: Load/earthquake thickness | P30: =(0.22*(P22+18)*(P25^2))/(P27*(P22^2)) -> 0.012667301
B31: Thickness | C31: in | D31: =IF(D8="Vertical", (D29+D29+D30)/2, D29 ) -> 0.39395338 | F31: Thickness | G31: in | H31: =IF(H8="Vertical", (H29+H29+H30)/2, H29 ) -> 0.5 | J31: Thickness | K31: in | L31: =IF(L8="Vertical", (L29+L29+L30)/2, L29 ) -> 0.5 | N31: Thickness | O31: in | P31: =IF(P8="Vertical", (P29+P29+P30)/2, P29 ) -> 0.4375
B32: Corrosion allowance | C32: mm | D32: =IF(AND(D7="CS",D9="N"),2,IF(AND(D7="CS",D9="Y"),4,3.175)) -> 3.175 | F32: Corrosion allowance | G32: mm | H32: =IF(AND(H7="CS",H9="N"),2,IF(AND(H7="CS",H9="Y"),4,3.175)) -> 3.175 | J32: Corrosion allowance | K32: mm | L32: =IF(AND(L7="CS",L9="N"),2,IF(AND(L7="CS",L9="Y"),4,3.175)) -> 3.175 | N32: Corrosion allowance | O32: mm | P32: =IF(AND(P7="CS",P9="N"),2,IF(AND(P7="CS",P9="Y"),4,3.175)) -> 3.175
B33: Corrosion allowance | C33: in | D33: =(D32/1000/0.3048)*12 -> 0.125 | F33: Corrosion allowance | G33: in | H33: =(H32/1000/0.3048)*12 -> 0.125 | J33: Corrosion allowance | K33: in | L33: =(L32/1000/0.3048)*12 -> 0.125 | N33: Corrosion allowance | O33: in | P33: =(P32/1000/0.3048)*12 -> 0.125
B34: Thickness | C34: in | D34: =D31+D33 -> 0.51895338 | F34: Thickness | G34: in | H34: =H31+H33 -> 0.625 | J34: Thickness | K34: in | L34: =L31+L33 -> 0.625 | N34: Thickness | O34: in | P34: =P31+P33 -> 0.5625
B35: Vessel Thickness | C35: in | D35: =CEILING( D34, IF(AND(D34>=3/16, D34<=1/2), 1/16, IF(AND(D34>=1/2, D34<=2), 1/8, IF(AND(D34>2, D34<=3), 1/4, 1/4 ))) ) -> 0.625 | F35: Vessel Thickness | G35: in | H35: =CEILING( H34, IF(AND(H34>=3/16, H34<=1/2), 1/16, IF(AND(H34>=1/2, H34<=2), 1/8, IF(AND(H34>2, H34<=3), 1/4, 1/4 ))) ) -> 0.625 | J35: Vessel Thickness | K35: in | L35: =CEILING( L34, IF(AND(L34>=3/16, L34<=1/2), 1/16, IF(AND(L34>=1/2, L34<=2), 1/8, IF(AND(L34>2, L34<=3), 1/4, 1/4 ))) ) -> 0.625 | N35: Vessel Thickness | O35: in | P35: =CEILING( P34, IF(AND(P34>=3/16, P34<=1/2), 1/16, IF(AND(P34>=1/2, P34<=2), 1/8, IF(AND(P34>2, P34<=3), 1/4, 1/4 ))) ) -> 0.625
B36: Material density | C36: lb/in3 | D36: =IF($D$7="","", INDEX(Data!$F:$F, MATCH($D$7, Data!$B:$B, 0))) -> 0.286 | F36: Material density | G36: lb/in3 | H36: =IF($D$7="","", INDEX(Data!$F:$F, MATCH($D$7, Data!$B:$B, 0))) -> 0.286 | J36: Material density | K36: lb/in3 | L36: =IF($D$7="","", INDEX(Data!$F:$F, MATCH($D$7, Data!$B:$B, 0))) -> 0.286 | N36: Material density | O36: lb/in3 | P36: =IF($D$7="","", INDEX(Data!$F:$F, MATCH($D$7, Data!$B:$B, 0))) -> 0.286
B37: Material density | C37: lb/ft3 | D37: =D36*12^3 -> 494.208 | F37: Material density | G37: lb/ft3 | H37: =H36*12^3 -> 494.208 | J37: Material density | K37: lb/ft3 | L37: =L36*12^3 -> 494.208 | N37: Material density | O37: lb/ft3 | P37: =P36*12^3 -> 494.208
B38: Weight | C38: lb | D38: =PI()*(D22+D35)*(D25+0.8*D22)*(D35*D36) -> 30063.917 | F38: Weight | G38: lb | H38: =PI()*(H22+H35)*(H25+0.8*H22)*(H35*H36) -> 219183.81 | J38: Weight | K38: lb | L38: =PI()*(L22+L35)*(L25+0.8*L22)*(L35*L36) -> 448687.32 | N38: Weight | O38: lb | P38: =PI()*(P22+P35)*(P25+0.8*P22)*(P35*P36) -> 25944.882
